<?xml version="1.0"?>
<robot xmlns:xacro="http://www.ros.org/wiki/xacro">

    <xacro:include filename="inertial_macros.xacro"/>

    <material name="white">
        <color rgba="1 1 1 1" />
    </material>

    <material name="orange">
        <color rgba="1 0.3 0.1 1"/>
    </material>

    <material name="blue">
        <color rgba="0.2 0.2 1 1"/>
    </material>

    <material name="black">
        <color rgba="0 0 0 1"/>
    </material>

    <!-- BASE LINK -->
    <link name="base_link">
    </link>

    <!-- CHASSIS LINK -->
    <link name="chassis">
        <visual>
            <origin xyz="0.45 0 0.075" />
            <geometry>
                <box size="0.9 0.3 0.15" />
            </geometry>
            <material name="white" />
        </visual>

        <collision>
            <origin xyz="0.45 0 0.075" />
            <geometry>
                <box size="0.9 0.3 0.15" />
            </geometry>
        </collision>

        <xacro:inertial_box mass="0.5" x="0.3" y="0.3" z="0.15">
            <origin xyz="0.15 0 0.075" rpy="0 0 0"/>
        </xacro:inertial_box>
    </link>

    <joint name="chassis_joint" type="fixed">
        <parent link="base_link" />
        <child link="chassis" />
        <origin xyz="-0.1 0 0" />
    </joint>

    <!-- LEFT WHEELS -->
    <!-- Left Wheel 1 -->
    <joint name="left_wheel_1_joint" type="continuous">
        <parent link="chassis"/>
        <child link="left_wheel_1"/>
        <origin xyz="0.1 0.175 0" rpy="1.5708 0 0"/>
        <axis xyz="0 0 1"/>
    </joint>

    <link name="left_wheel_1">
        <visual>
            <geometry>
                <cylinder radius="0.05" length="0.04"/>
            </geometry>
            <material name="blue"/>
        </visual>

        <collision>
            <geometry>
                <cylinder radius="0.05" length="0.04"/>
            </geometry>
        </collision>

        <xacro:inertial_cylinder mass="0.1" length="0.04" radius="0.05">
            <origin xyz="0 0 0" rpy="0 0 0"/>
        </xacro:inertial_cylinder>
    </link>
    <gazebo reference="left_wheel_1">
        <material>Gazebo/Black</material>
    </gazebo>    

    <!-- Left Wheel 2 -->
    <joint name="left_wheel_2_joint" type="continuous">
        <parent link="chassis"/>
        <child link="left_wheel_2"/>
        <origin xyz="0.4 0.175 0" rpy="1.5708 0 0"/>
        <axis xyz="0 0 1"/>
    </joint>

    <link name="left_wheel_2">
        <visual>
            <geometry>
                <cylinder radius="0.05" length="0.04"/>
            </geometry>
            <material name="blue"/>
        </visual>

        <collision>
            <geometry>
                <cylinder radius="0.05" length="0.04"/>
            </geometry>
        </collision>

        <xacro:inertial_cylinder mass="0.1" length="0.04" radius="0.05">
            <origin xyz="0 0 0" rpy="0 0 0"/>
        </xacro:inertial_cylinder>
    </link>
    <gazebo reference="left_wheel_2">
        <material>Gazebo/Blue</material>
    </gazebo>

    <!-- Left Wheel 3 -->
    <joint name="left_wheel_3_joint" type="continuous">
        <parent link="chassis"/>
        <child link="left_wheel_3"/>
        <origin xyz="0.7 0.175 0" rpy="1.5708 0 0"/>
        <axis xyz="0 0 1"/>
    </joint>

    <link name="left_wheel_3">
        <visual>
            <geometry>
                <cylinder radius="0.05" length="0.04"/>
            </geometry>
            <material name="blue"/>
        </visual>

        <collision>
            <geometry>
                <cylinder radius="0.05" length="0.04"/>
            </geometry>
        </collision>

        <xacro:inertial_cylinder mass="0.1" length="0.04" radius="0.05">
            <origin xyz="0 0 0" rpy="0 0 0"/>
        </xacro:inertial_cylinder>
    </link>
    <gazebo reference="left_wheel_3">
        <material>Gazebo/Blue</material>
    </gazebo>

    <!-- RIGHT WHEELS -->
    <!-- Right Wheel 1 -->
    <joint name="right_wheel_1_joint" type="continuous">
        <parent link="chassis"/>
        <child link="right_wheel_1"/>
        <origin xyz="0.1 -0.175 0" rpy="1.5708 0 0"/>
        <axis xyz="0 0 1"/>
    </joint>

    <link name="right_wheel_1">
        <visual>
            <geometry>
                <cylinder radius="0.05" length="0.04"/>
            </geometry>
            <material name="blue"/>
        </visual>

        <collision>
            <geometry>
                <cylinder radius="0.05" length="0.04"/>
            </geometry>
        </collision>

        <xacro:inertial_cylinder mass="0.1" length="0.04" radius="0.05">
            <origin xyz="0 0 0" rpy="0 0 0"/>
        </xacro:inertial_cylinder>
    </link>

    <gazebo reference="right_wheel_1">
        <material>Gazebo/Black</material>
    </gazebo>

    <!-- Right Wheel 2 -->
    <joint name="right_wheel_2_joint" type="continuous">
        <parent link="chassis"/>
        <child link="right_wheel_2"/>
        <origin xyz="0.4 -0.175 0" rpy="1.5708 0 0"/>
        <axis xyz="0 0 1"/>
    </joint>

    <link name="right_wheel_2">
        <visual>
            <geometry>
                <cylinder radius="0.05" length="0.04"/>
            </geometry>
            <material name="blue"/>
        </visual>

        <collision>
            <geometry>
                <cylinder radius="0.05" length="0.04"/>
            </geometry>
        </collision>

        <xacro:inertial_cylinder mass="0.1" length="0.04" radius="0.05">
            <origin xyz="0 0 0" rpy="0 0 0"/>
        </xacro:inertial_cylinder>
    </link>

    <gazebo reference="right_wheel_2">
        <material>Gazebo/Blue</material>
    </gazebo>
    <!-- Right Wheel 3 -->
    <joint name="right_wheel_3_joint" type="continuous">
        <parent link="chassis"/>
        <child link="right_wheel_3"/>
        <origin xyz="0.7 -0.175 0" rpy="1.5708 0 0"/>
        <axis xyz="0 0 1"/>
    </joint>

    <link name="right_wheel_3">
        <visual>
            <geometry>
                <cylinder radius="0.05" length="0.04"/>
            </geometry>
            <material name="blue"/>
        </visual>

        <collision>
            <geometry>
                <cylinder radius="0.05" length="0.04"/>
            </geometry>
        </collision>

        <xacro:inertial_cylinder mass="0.1" length="0.04" radius="0.05">
            <origin xyz="0 0 0" rpy="0 0 0"/>
        </xacro:inertial_cylinder>
    </link>
        <gazebo reference="right_wheel_3">
        <material>Gazebo/Blue</material>
    </gazebo>

</robot>
